<?xml version="1.0" ?>

<robot name="ibrain" xmlns:xacro="https://www.ros.org/wiki/xacro" >


  <!-- <xacro:include filename="$(find ibrain)/urdf/kinect_camera.urdf.xacro" /> -->

  
  
  <gazebo reference="link_chassis">
    <material>Gazebo/Orange</material>
  </gazebo>

  <gazebo reference="link_left_wheel">
    <material>Gazebo/Blue</material>
  </gazebo>

  <gazebo reference="link_right_wheel">
    <material>Gazebo/Blue</material>
  </gazebo>

  <gazebo reference="link_right_wheel2">
    <material>Gazebo/Blue</material>
  </gazebo>

  <gazebo reference="link_left_wheel2">
    <material>Gazebo/Blue</material>
  </gazebo>  

   <gazebo reference="body">
		<material>Gazebo/DarkGrey</material>
	</gazebo>

   <gazebo reference="upper_body">
		<material>Gazebo/Black</material>
	</gazebo>

  <link name="link_chassis">
    <!-- pose and inertial -->
    <pose>0 0 0.1 0 0 0</pose>
    
    <inertial>
      <mass value="50"/>
      <origin rpy="0 0 0" xyz="0 0 0.1"/>
      <inertia ixx="0.0395416666667" ixy="0" ixz="0" iyy="0.106208333333" iyz="0" izz="0.106208333333"/>
    </inertial>
    
    <collision name="collision_chassis">
      <geometry>
        <box size="0.4 0.4 0.05"/>
      </geometry>
    </collision>
    
    <visual>
      <origin rpy="0 0 0" xyz="0 0 0"/>
      <geometry>
        <box size="0.4 0.4 0.05"/>
      </geometry>
      <material name="blue"/>
    </visual>
  </link>
  
  <!-- Create wheel right -->  
    
  <link name="link_right_wheel">    
    <inertial>
      <mass value="0.2"/>
      <origin rpy="0 1.5707 1.5707" xyz="0 0 0"/>
      <inertia ixx="0.00052666666" ixy="0" ixz="0" iyy="0.00052666666" iyz="0" izz="0.001"/>
    </inertial>
    
    <collision name="link_right_wheel_collision">
      <origin rpy="0 1.5707 1.5707" xyz="0 0 0" />
      <geometry>
        <cylinder length="0.04" radius="0.05"/>
      </geometry>
    </collision>
    
    <visual name="link_right_wheel_visual">
      <origin rpy="0 1.5707 1.5707" xyz="0 0 0"/>
      <geometry>
        <cylinder length="0.04" radius="0.05"/>
      </geometry>      
    </visual>
    
  </link>
    
  <!--   Joint for right wheel  -->
  <joint name="joint_right_wheel" type="continuous">
    <origin rpy="0 0 0" xyz="-0.1 0.23 0"/>
    <child link="link_right_wheel" />
    <parent link="link_chassis"/>
    <axis rpy="0 0 0" xyz="0 1 0"/>
    <limit effort="10000" velocity="1000"/>
    <joint_properties damping="1.0" friction="1.0" />
  </joint>  
    
  
  <link name="link_right_wheel2">    
    <inertial>
      <mass value="0.2"/>
      <origin rpy="0 1.5707 1.5707" xyz="0 0 0"/>
      <inertia ixx="0.00052666666" ixy="0" ixz="0" iyy="0.00052666666" iyz="0" izz="0.001"/>
    </inertial>
    
    <collision name="link_right_wheel_collision">
      <origin rpy="0 1.5707 1.5707" xyz="0 0 0" />
      <geometry>
        <cylinder length="0.04" radius="0.05"/>
      </geometry>
    </collision>
    
    <visual name="link_right_wheel_visual">
      <origin rpy="0 1.5707 1.5707" xyz="0 0 0"/>
      <geometry>
        <cylinder length="0.04" radius="0.05"/>
      </geometry>      
    </visual>
    
  </link>
    
  <!--   Joint for right wheel  -->
  <joint name="joint_right_wheel2" type="continuous">
    <origin rpy="0 0 0" xyz="0.1 0.23 0"/>
    <child link="link_right_wheel2" />
    <parent link="link_chassis"/>
    <axis rpy="0 0 0" xyz="0 1 0"/>
    <limit effort="10000" velocity="1000"/>
    <joint_properties damping="1.0" friction="1.0" />
  </joint>  
    
  <!-- Left Wheel link -->
    
  <link name="link_left_wheel">    
    <inertial>
      <mass value="0.2"/>
      <origin rpy="0 1.5707 1.5707" xyz="0 0 0"/>
      <inertia ixx="0.00052666666" ixy="0" ixz="0" iyy="0.00052666666" iyz="0" izz="0.001"/>
    </inertial>
    
    <collision name="link_left_wheel2_collision">
      <origin rpy="0 1.5707 1.5707" xyz="0 0 0" />
      <geometry>
        <cylinder length="0.04" radius="0.05"/>
      </geometry>
    </collision>
    
    <visual name="link_left_wheel2_visual">
      <origin rpy="0 1.5707 1.5707" xyz="0 0 0"/>
      <geometry>
        <cylinder length="0.04" radius="0.05"/>
      </geometry>      
    </visual>
    
  </link>
    
  <!--   Joint for left wheel  -->
  <joint name="joint_left_wheel" type="continuous">
    <origin rpy="0 0 0" xyz="-0.1 -0.23 0"/>
    <child link="link_left_wheel" />
    <parent link="link_chassis"/>
    <axis rpy="0 0 0" xyz="0 1 0"/>
    <limit effort="10000" velocity="1000"/>
    <joint_properties damping="1.0" friction="1.0" />
  </joint>    

    <!-- Left Wheel link 2-->
    
  <link name="link_left_wheel2">    
    <inertial>
      <mass value="0.2"/>
      <origin rpy="0 1.5707 1.5707" xyz="0 0 0"/>
      <inertia ixx="0.00052666666" ixy="0" ixz="0" iyy="0.00052666666" iyz="0" izz="0.001"/>
    </inertial>
    
    <collision name="link_left_wheel2_collision">
      <origin rpy="0 1.5707 1.5707" xyz="0 0 0" />
      <geometry>
        <cylinder length="0.04" radius="0.05"/>
      </geometry>
    </collision>
    
    <visual name="link_left_wheel2_visual">
      <origin rpy="0 1.5707 1.5707" xyz="0 0 0"/>
      <geometry>
        <cylinder length="0.04" radius="0.05"/>
      </geometry>      
    </visual>
    
  </link>
    
  <!--   Joint for left wheel 2 -->
  <joint name="joint_left_wheel2" type="continuous">
    <origin rpy="0 0 0" xyz="0.1 -0.23 0"/>
    <child link="link_left_wheel2" />
    <parent link="link_chassis"/>
    <axis rpy="0 0 0" xyz="0 1 0"/>
    <limit effort="10000" velocity="1000"/>
    <joint_properties damping="1.0" friction="1.0" />
  </joint>    


 <!-- body -->
    <link name="body">
    <pose>0 0 0.1 0 0 0</pose>
    
    <inertial>
      <mass value="20"/>
      <origin rpy="0 0 0" xyz="0 0 0"/>
      <inertia ixx="0.0395416666667" ixy="0" ixz="0" iyy="0.106208333333" iyz="0" izz="0.106208333333"/>
    </inertial>
    
    <collision name="collision_body">
      <geometry>
        <box size="0.2 0.2 1.1"/>
      </geometry>
    </collision>
    
    <visual>
      <origin rpy="0 0 0" xyz="0 0 0"/>
      <geometry>
        <box size="0.07 0.2 1.1"/>
      </geometry>
    </visual>
  </link>
 
  
    <joint name="body_joint" type="fixed">
    <origin rpy="0 0 0" xyz="0.0 0.0 0.55"/>
    <child link="body" />
    <parent link="link_chassis"/>
    <axis rpy="0 0 0" xyz="1 0 0"/>
    <limit effort="10000" velocity="1000"/>
    <joint_properties damping="1.0" friction="1.0" />
  </joint>   

   <!-- upper_body -->
    <link name="upper_body">
    <pose>0 0 0.1 0 0 0</pose>
    
    <inertial>
      <mass value="5"/>
      <origin rpy="0 0 0" xyz="0 0 0"/>
      <inertia ixx="0.0395416666667" ixy="0" ixz="0" iyy="0.106208333333" iyz="0" izz="0.106208333333"/>
    </inertial>
    
    <collision name="collision_upper_body">
      <geometry>
        <box size="0.5 0.5 0.7"/>
      </geometry>
    </collision>
    
    <visual>
      <origin rpy="0 0 0" xyz="0 0 0"/>
      <geometry>
        <box size="0.1 0.5 0.7"/>
      </geometry>
      <material name="red"/>
    </visual>
  </link>
  
    <joint name="upper_body_joint" type="fixed">
    <origin rpy="0 0 0" xyz="0.0 0.0 1.1"/>
    <child link="upper_body" />
    <parent link="link_chassis"/>
    <axis rpy="0 0 0" xyz="1 0 0"/>
    <limit effort="10000" velocity="1000"/>
    <joint_properties damping="1.0" friction="1.0" />
  </joint>  



  <!-- <kinect_camera parent="upper_body" name="camera">
    <origin xyz="0.05 0.0 -0.36" rpy="0 0 0"/>
  </kinect_camera> -->


<!-- inner_body -->
    <link name="inner_body">
    <pose>0 0 0.1 0 0 0</pose>
    
    <inertial>
      <mass value="5"/>
      <origin rpy="0 0 0" xyz="0 0 0"/>
      <inertia ixx="0.0395416666667" ixy="0" ixz="0" iyy="0.106208333333" iyz="0" izz="0.106208333333"/>
    </inertial>
    
    <collision name="collision_inner_body">
      <geometry>
        <box size="0.5 0.3 0.6"/>
      </geometry>
    </collision>
    
    <visual>
      <origin rpy="0 0 0" xyz="0 0 0"/>
      <geometry>
        <box size="0.15 0.3 0.6"/>
      </geometry>
    </visual>
  </link>
  
    <joint name="inner_body_joint" type="fixed">
    <origin rpy="0 0 0" xyz="0.0 0.0 1.1"/>
    <child link="inner_body" />
    <parent link="link_chassis"/>
    <axis rpy="0 0 0" xyz="1 0 0"/>
    <limit effort="10000" velocity="1000"/>
    <joint_properties damping="1.0" friction="1.0" />
  </joint>  

  <!-- Lidar1 -->

   <link name="sensor_laser1">
    <inertial>
      <origin xyz="0 0 0" rpy="0 0 0" />
      <mass value="1" />
      <!-- RANDOM INERTIA BELOW -->
      <inertia ixx="0.02" ixy="0" ixz="0" iyy="0.02" iyz="0" izz="0.02"/>
    </inertial>

    <visual>
      <origin xyz="0 0 0" rpy="0 0 0" />
      <geometry>
        <cylinder radius="0.05" length="0.1"/>
      </geometry>
    </visual>

    <collision>
      <origin xyz="0 0 0" rpy="0 0 0"/>
      <geometry>
        <cylinder radius="0.05" length="0.1"/>
      </geometry>
    </collision>
  </link>

  <joint name="joint_sensor_laser1" type="fixed">
    <origin xyz="0.15 0 0.1" rpy="0 0 0"/>
    <parent link="link_chassis"/>
    <child link="sensor_laser1"/>
  </joint>


 <gazebo>
		<plugin filename="libgazebo_ros_control.so" name="gazebo_ros_control">
			<robotNamespace>/</robotNamespace>
			<robotSimType>gazebo_ros_control/DefaultRobotHWSim</robotSimType>
			<legacyModeNS>true</legacyModeNS>
		</plugin>
	</gazebo> 

	<gazebo>
		<plugin filename="libgazebo_ros_diff_drive.so" name="differential_drive_controller">
			<legacyMode>false</legacyMode>
			<alwaysOn>true</alwaysOn>
			<updateRate>20</updateRate>
			<leftJoint>joint_right_wheel</leftJoint>
      <leftJoint>joint_right_wheel2</leftJoint>
			<rightJoint>joint_left_wheel</rightJoint>
    	<rightJoint>joint_left_wheel2</rightJoint>
			<wheelSeparation>0.53</wheelSeparation>
			<wheelDiameter>0.1524</wheelDiameter>
			<commandTopic>cmd_vel</commandTopic>
			<odometryTopic>odom</odometryTopic>
			<odometryFrame>odom</odometryFrame>
			<robotBaseFrame>link_chassis</robotBaseFrame>
      <robotNamespace>/</robotNamespace>
		</plugin>
	</gazebo>

  	<!--Lidar1-->

	<gazebo reference="sensor_laser1">
		<sensor type="ray" name="head_hokuyo_sensor1">
			<pose>0 0 0 0 0 0</pose>
			<visualize>false</visualize>
			<update_rate>10</update_rate>
			<ray>
				<scan>
					<horizontal>
						<samples>720</samples>
						<resolution>1</resolution>
						<min_angle>-1.5</min_angle>
						<max_angle>1.5</max_angle>
					</horizontal>
				</scan>
				<range>
					<min>0.15</min>
					<max>8.0</max>
					<resolution>0.01</resolution>
				</range>
				<noise>
					<type>gaussian</type>
					<mean>0.0</mean>
					<stddev>0.01</stddev>
				</noise>
			</ray>
			<plugin name="gazebo_ros_head_hokuyo_controller" filename="libgazebo_ros_laser.so">
				<topicName>/scan1</topicName>
				<frameName>sensor_laser1</frameName>
			</plugin>
		</sensor>
	</gazebo>
  
  <!-- imu --> 
    <!-- <gazebo>
    <plugin name="imu_plugin" filename="libgazebo_ros_imu.so">
      <alwaysOn>true</alwaysOn>
      <bodyName>camera_link</bodyName>
      <topicName>imu</topicName>
      <serviceName>imu_service</serviceName>
      <gaussianNoise>0.0</gaussianNoise>
      <updateRate>20.0</updateRate>
    </plugin>
  </gazebo> -->

<joint name="camera_joint" type="fixed">
        <parent link="upper_body"/>
        <child link="camera_link"/>
      </joint>

      <link name="camera_link">
        <inertial_sphere mass="0.01" diameter="0.07" />
        <visual>
          <origin xyz="0 0 0" rpy="0 0 0" />
          <geometry>
            <mesh filename="package://ibrain/meshes/kinect.dae"/>
          </geometry>
        </visual>
        <collision>
          <origin xyz="0 0 0" rpy="0 0 0" />
          <geometry>
            <mesh filename="package://ibrain/meshes/kinect.dae"/>
          </geometry>
        </collision>
      </link>

      <joint name="camera_depth_joint" type="fixed">
        <origin xyz="0.0 -0.02 0.0" rpy="0 0 0" />
        <parent link="camera_link" />
        <child link="camera_depth_frame"/>
      </joint>

      <link name="camera_depth_frame"/>

      <joint name="camera_depth_optical_joint" type="fixed">
        <origin xyz="0 0 0" rpy="${-3.14/2} 0.0 ${-3.14/2}" />
        <parent link="camera_depth_frame" />
        <child link="camera_depth_optical_frame"/>
      </joint>

      <link name="camera_depth_optical_frame"/>

      <joint name="camera_rgb_joint" type="fixed">
        <origin xyz="0.0 -0.0125 0.0" rpy="0 0 0" />
        <parent link="camera_link" />
        <child link="camera_rgb_frame"/>
      </joint>

      <link name="camera_rgb_frame"/>

      <joint name="camera_rgb_optical_joint" type="fixed">
        <origin xyz="0 0 0" rpy="${-3.14/2} 0.0 ${-3.14/2}" />
        <parent link="camera_rgb_frame" />
        <child link="camera_rgb_optical_frame"/>
      </joint>

      <link name="camera_rgb_optical_frame"/>


      <gazebo reference="camera_depth_frame">
        <sensor type="depth" name="camera">
          <update_rate>20</update_rate>
          <camera>
            <horizontal_fov>${60 * 3.14/180.0}</horizontal_fov>
            <image>
              <format>R8G8B8</format>
              <width>640</width>
              <height>480</height>
            </image>
            <clip>
              <near>0.05</near>
              <far>3</far>
            </clip>
          </camera>
          <plugin name="camera_camera_controller" filename="libgazebo_ros_openni_kinect.so">
            <alwaysOn>true</alwaysOn>
            <updateRate>20</updateRate>
            <imageTopicName>camera/rgb/image_raw</imageTopicName>
            <cameraInfoTopicName>camera/rgb/camera_info</cameraInfoTopicName>
            <depthImageTopicName>camera/depth/image_raw</depthImageTopicName>
            <depthImageCameraInfoTopicName>camera/depth/camera_info</depthImageCameraInfoTopicName>
            <pointCloudTopicName>camera/depth/points</pointCloudTopicName>
            <frameName>camera_depth_optical_frame</frameName>
            <distortion_k1>0.0</distortion_k1>
            <distortion_k2>0.0</distortion_k2>
            <distortion_k3>0.0</distortion_k3>
            <distortion_t1>0.0</distortion_t1>
            <distortion_t2>0.0</distortion_t2>
          </plugin>
        </sensor>
      </gazebo>
 
 



  

</robot>
